Workbook

Sheet Fight card
A1: SHIDOKAN CHALLENGE 974 — ORDRE DES COMBATS | N1: Combats | O1: =COUNTA(I6:I200) -> 28
A2: Dimanche 25 octobre 2026 · Gymnase du 12ème km, Le Tampon · 8h30 – 15h · 2 aires | N2: Terminés | O2: =COUNTIF(M6:M200,"Terminé") -> 0
A3: Cases jaunes = à modifier (listes déroulantes pour aire, combattants, statut, vainqueur, méthode). Colonnes blanches = calculées automatiquement. Ajoutez des combats en bas du tableau. | N3: Restants | O3: =O1-O2 -> 28
A5: N° | B5: Heure | C5: Aire | D5: Partie | E5: Catégorie | F5: Phase | G5: Discipline | H5: Format | I5: 🔴 Coin rouge (Aka) | J5: Club | K5: 🔵 Coin bleu (Ao) | L5: Club | M5: Statut | N5: Vainqueur (coin) | O5: Vainqueur (nom) | P5: Méthode | Q5: Reprise | R5: Notes
A6: 1 | B6: 09h20 | C6: 1 | D6: Matin · Enfants | E6: Filles 23-24 kg | F6: Combat unique | G6: Karaté Shidokan | H6: 1 min 30 | I6: Kiria BOYER | J6: =IFERROR(INDEX(Combattants!$E$2:$E$200,MATCH(I6,Combattants!$A$2:$A$200,0)),"") -> FUK | K6: Camilya BACAR | L6: =IFERROR(INDEX(Combattants!$E$2:$E$200,MATCH(K6,Combattants!$A$2:$A$200,0)),"") -> FUK | M6: Prévu | O6: =IF(N6="Rouge",I6,IF(N6="Bleu",K6,IF(N6="Nul","Match nul","")))
A7: 2 | B7: 09h20 | C7: 2 | D7: Matin · Enfants | E7: Filles 27-30 kg | F7: Combat unique | G7: Karaté Shidokan | H7: 1 min 30 | I7: Inès ICHARD | J7: =IFERROR(INDEX(Combattants!$E$2:$E$200,MATCH(I7,Combattants!$A$2:$A$200,0)),"") -> FUK | K7: Lucie PAYET | L7: =IFERROR(INDEX(Combattants!$E$2:$E$200,MATCH(K7,Combattants!$A$2:$A$200,0)),"") -> MAN | M7: Prévu | O7: =IF(N7="Rouge",I7,IF(N7="Bleu",K7,IF(N7="Nul","Match nul","")))
A8: 3 | B8: 09h24 | C8: 1 | D8: Matin · Enfants | E8: Filles 34-35 kg | F8: Combat unique | G8: Karaté Shidokan | H8: 1 min 30 | I8: Elie-Rose THOMAS | J8: =IFERROR(INDEX(Combattants!$E$2:$E$200,MATCH(I8,Combattants!$A$2:$A$200,0)),"") -> FUK | K8: Lily BEGUE | L8: =IFERROR(INDEX(Combattants!$E$2:$E$200,MATCH(K8,Combattants!$A$2:$A$200,0)),"") -> MAN | M8: Prévu | O8: =IF(N8="Rouge",I8,IF(N8="Bleu",K8,IF(N8="Nul","Match nul","")))
A9: 4 | B9: 09h24 | C9: 2 | D9: Matin · Enfants | E9: Filles minimes 55 kg | F9: Combat unique | G9: Karaté Shidokan | H9: 1 min 30 | I9: EVE RIVIERE | J9: =IFERROR(INDEX(Combattants!$E$2:$E$200,MATCH(I9,Combattants!$A$2:$A$200,0)),"") -> MAN | K9: HELENA PAYET | L9: =IFERROR(INDEX(Combattants!$E$2:$E$200,MATCH(K9,Combattants!$A$2:$A$200,0)),"") -> MAN | M9: Prévu | O9: =IF(N9="Rouge",I9,IF(N9="Bleu",K9,IF(N9="Nul","Match nul","")))
A10: 5 | B10: 09h28 | C10: 1 | D10: Matin · Enfants | E10: Cadette 50 kg (boxing) | F10: Exhibition | G10: Shidoboxing | H10: 1 min 30 | I10: Chloé FONTAINE | J10: =IFERROR(INDEX(Combattants!$E$2:$E$200,MATCH(I10,Combattants!$A$2:$A$200,0)),"") -> SHO | K10: Adversaire à définir | L10: =IFERROR(INDEX(Combattants!$E$2:$E$200,MATCH(K10,Combattants!$A$2:$A$200,0)),"") | M10: Prévu | O10: =IF(N10="Rouge",I10,IF(N10="Bleu",K10,IF(N10="Nul","Match nul","")))
A11: 6 | B11: 09h28 | C11: 2 | D11: Matin · Enfants | E11: Cadette 64 kg | F11: Exhibition | G11: Karaté Shidokan | H11: 1 min 30 | I11: Lanah BARDINOT | J11: =IFERROR(INDEX(Combattants!$E$2:$E$200,MATCH(I11,Combattants!$A$2:$A$200,0)),"") -> SHO | K11: Adversaire à définir | L11: =IFERROR(INDEX(Combattants!$E$2:$E$200,MATCH(K11,Combattants!$A$2:$A$200,0)),"") | M11: Prévu | O11: =IF(N11="Rouge",I11,IF(N11="Bleu",K11,IF(N11="Nul","Match nul","")))
A12: 7 | B12: 09h32 | C12: 1 | D12: Matin · Enfants | E12: Filles 35-38 kg | F12: Combat unique | G12: Karaté Shidokan | H12: 1 min 30 | I12: Melina FOLIO | J12: =IFERROR(INDEX(Combattants!$E$2:$E$200,MATCH(I12,Combattants!$A$2:$A$200,0)),"") -> FAK | K12: Lily BEGUE | L12: =IFERROR(INDEX(Combattants!$E$2:$E$200,MATCH(K12,Combattants!$A$2:$A$200,0)),"") -> MAN | M12: Prévu | O12: =IF(N12="Rouge",I12,IF(N12="Bleu",K12,IF(N12="Nul","Match nul","")))
A13: 8 | B13: 09h32 | C13: 2 | D13: Matin · Enfants | E13: Garçons 23-24 kg | F13: Combat unique | G13: Karaté Shidokan | H13: 1 min 30 | I13: Logan PROST | J13: =IFERROR(INDEX(Combattants!$E$2:$E$200,MATCH(I13,Combattants!$A$2:$A$200,0)),"") -> FUK | K13: Raphaël FRAYNAL | L13: =IFERROR(INDEX(Combattants!$E$2:$E$200,MATCH(K13,Combattants!$A$2:$A$200,0)),"") -> FAK | M13: Prévu | O13: =IF(N13="Rouge",I13,IF(N13="Bleu",K13,IF(N13="Nul","Match nul","")))
A14: 9 | B14: 09h36 | C14: 1 | D14: Matin · Enfants | E14: Garçons 34-35 kg | F14: Combat unique | G14: Karaté Shidokan | H14: 1 min 30 | I14: Antoine RIVIERE | J14: =IFERROR(INDEX(Combattants!$E$2:$E$200,MATCH(I14,Combattants!$A$2:$A$200,0)),"") -> MAN | K14: Basile ABEL | L14: =IFERROR(INDEX(Combattants!$E$2:$E$200,MATCH(K14,Combattants!$A$2:$A$200,0)),"") -> FUK | M14: Prévu | O14: =IF(N14="Rouge",I14,IF(N14="Bleu",K14,IF(N14="Nul","Match nul","")))
A15: 10 | B15: 09h36 | C15: 2 | D15: Matin · Enfants | E15: Garçons 35 kg | F15: Combat unique | G15: Karaté Shidokan | H15: 1 min 30 | I15: HUGO GRONDIN | J15: =IFERROR(INDEX(Combattants!$E$2:$E$200,MATCH(I15,Combattants!$A$2:$A$200,0)),"") -> MAN | K15: Nathan BABEF | L15: =IFERROR(INDEX(Combattants!$E$2:$E$200,MATCH(K15,Combattants!$A$2:$A$200,0)),"") -> FUK | M15: Prévu | O15: =IF(N15="Rouge",I15,IF(N15="Bleu",K15,IF(N15="Nul","Match nul","")))
A16: 11 | B16: 09h40 | C16: 1 | D16: Matin · Enfants | E16: Garçons 35 kg | F16: Combat unique | G16: Karaté Shidokan | H16: 1 min 30 | I16: Lorentz PAYET | J16: =IFERROR(INDEX(Combattants!$E$2:$E$200,MATCH(I16,Combattants!$A$2:$A$200,0)),"") -> FAK | K16: Mahé PASQUET | L16: =IFERROR(INDEX(Combattants!$E$2:$E$200,MATCH(K16,Combattants!$A$2:$A$200,0)),"") -> FUK | M16: Prévu | O16: =IF(N16="Rouge",I16,IF(N16="Bleu",K16,IF(N16="Nul","Match nul","")))
A17: 12 | B17: 09h40 | C17: 2 | D17: Matin · Enfants | E17: Garçons 36,5-37 kg | F17: Combat unique | G17: Karaté Shidokan | H17: 1 min 30 | I17: NOA ZAMBERNARDI | J17: =IFERROR(INDEX(Combattants!$E$2:$E$200,MATCH(I17,Combattants!$A$2:$A$200,0)),"") -> FAK | K17: AXEL DUHOU | L17: =IFERROR(INDEX(Combattants!$E$2:$E$200,MATCH(K17,Combattants!$A$2:$A$200,0)),"") -> FUK | M17: Prévu | O17: =IF(N17="Rouge",I17,IF(N17="Bleu",K17,IF(N17="Nul","Match nul","")))
... A28: 23 | B28: 13h20 | C28: 2 | D28: Après-midi · Adultes | E28: Seniors H 78-84 kg | F28: Combat unique | G28: Karaté Shidokan | H28: 2 min | I28: Sébastien ELIE | J28: =IFERROR(INDEX(Combattants!$E$2:$E$200,MATCH(I28,Combattants!$A$2:$A$200,0)),"") -> FUK | K28: Thomas GUICHARD | L28: =IFERROR(INDEX(Combattants!$E$2:$E$200,MATCH(K28,Combattants!$A$2:$A$200,0)),"") -> SHO | M28: Prévu | O28: =IF(N28="Rouge",I28,IF(N28="Bleu",K28,IF(N28="Nul","Match nul","")))
A29: 24 | B29: 13h25 | C29: 1 | D29: Après-midi · Adultes | E29: MMA -80 kg | F29: Combat unique | G29: Shido-MMA | H29: 2 min | I29: Miguel IBAO | J29: =IFERROR(INDEX(Combattants!$E$2:$E$200,MATCH(I29,Combattants!$A$2:$A$200,0)),"") -> SHO | K29: MATHIAS DIJOUX | L29: =IFERROR(INDEX(Combattants!$E$2:$E$200,MATCH(K29,Combattants!$A$2:$A$200,0)),"") -> MAN | M29: Prévu | O29: =IF(N29="Rouge",I29,IF(N29="Bleu",K29,IF(N29="Nul","Match nul",""))) | R29: Co-vedette
A30: 25 | B30: 13h25 | C30: 2 | D30: Après-midi · Adultes | E30: Seniors H 98-100 kg | F30: Combat unique | G30: Karaté Shidokan | H30: 2 min | I30: Clément DELMAS | J30: =IFERROR(INDEX(Combattants!$E$2:$E$200,MATCH(I30,Combattants!$A$2:$A$200,0)),"") -> FUK | K30: CEDRIC PAYET | L30: =IFERROR(INDEX(Combattants!$E$2:$E$200,MATCH(K30,Combattants!$A$2:$A$200,0)),"") -> MAN | M30: Prévu | O30: =IF(N30="Rouge",I30,IF(N30="Bleu",K30,IF(N30="Nul","Match nul","")))
A31: 26 | B31: 13h30 | C31: 1 | D31: Après-midi · Adultes | E31: Seniors H 60-66 kg | F31: Combat unique | G31: Karaté Shidokan | H31: 2 min | I31: THEO FONTAINE | J31: =IFERROR(INDEX(Combattants!$E$2:$E$200,MATCH(I31,Combattants!$A$2:$A$200,0)),"") -> MAN | K31: Jonathan BOYER | L31: =IFERROR(INDEX(Combattants!$E$2:$E$200,MATCH(K31,Combattants!$A$2:$A$200,0)),"") -> FAK | M31: Prévu | O31: =IF(N31="Rouge",I31,IF(N31="Bleu",K31,IF(N31="Nul","Match nul","")))
A32: 27 | B32: 13h30 | C32: 2 | D32: Après-midi · Adultes | E32: Seniors H 79-84 kg | F32: Combat unique | G32: Karaté Shidokan | H32: 2 min | I32: Guillaume PASQUET | J32: =IFERROR(INDEX(Combattants!$E$2:$E$200,MATCH(I32,Combattants!$A$2:$A$200,0)),"") -> FUK | K32: Thomas GUICHARD | L32: =IFERROR(INDEX(Combattants!$E$2:$E$200,MATCH(K32,Combattants!$A$2:$A$200,0)),"") -> SHO | M32: Prévu | O32: =IF(N32="Rouge",I32,IF(N32="Bleu",K32,IF(N32="Nul","Match nul","")))
A33: 28 | B33: 13h35 | C33: 1 | D33: Après-midi · Adultes | E33: Seniors H 100-106 kg | F33: Combat unique | G33: Karaté Shidokan | H33: 2 min | I33: CEDRIC PAYET | J33: =IFERROR(INDEX(Combattants!$E$2:$E$200,MATCH(I33,Combattants!$A$2:$A$200,0)),"") -> MAN | K33: Salim YOUSSOUF | L33: =IFERROR(INDEX(Combattants!$E$2:$E$200,MATCH(K33,Combattants!$A$2:$A$200,0)),"") -> FUK | M33: Prévu | O33: =IF(N33="Rouge",I33,IF(N33="Bleu",K33,IF(N33="Nul","Match nul",""))) | R33: Combat vedette

Sheet Programme
A1: Événement | B1: Shidokan Challenge 974
A2: Date | B2: Dimanche 25 octobre 2026
A3: Lieu | B3: Gymnase du 12ème km · Le Tampon
A4: Horaires | B4: 8h30 – 15h
A5: Organisation | B5: Fighter Academy Karaté
A6: Aires de combat | B6: 2
A7: Barème poules | B7: Victoire 3 · Nul 1 · Défaite 0
A9: Heure | B9: Étape
A10: 8h30 | B10: Accueil & pesée
A11: 9h00 | B11: Ouverture & salut
A12: 9h20 | B12: Combats enfants · 1'30
A13: 12h15 | B13: Pause déjeuner
A14: 13h15 | B14: Combats adultes · 2'
A15: 14h30 | B15: Podiums · fin 15h
A17: Source : application de pilotage Shidokan Challenge 974, état du 20 octobre 2026.

Sheet Combattants
A1: Nom affiché | B1: Prénom | C1: Nom | D1: Club | E1: Code | F1: Sexe | G1: Catégorie d'âge | H1: Catégorie de poids | I1: Poids déclaré (kg) | J1: Poids pesée (kg) | K1: Disciplines | L1: Nb de combats | M1: Notes
A2: =TRIM(B2&" "&C2) -> Ethan ICAZE | B2: Ethan | C2: ICAZE | D2: Fighter Academy Karaté | E2: =IFERROR(INDEX(Clubs!$B$2:$B$20,MATCH(D2,Clubs!$A$2:$A$20,0)),"") -> FAK | F2: H | G2: Cadets | K2: Karaté Shidokan | L2: =COUNTIF('Fight card'!$I$6:$I$200,A2)+COUNTIF('Fight card'!$K$6:$K$200,A2) -> 1
A3: =TRIM(B3&" "&C3) -> Jonathan BOYER | B3: Jonathan | C3: BOYER | D3: Fighter Academy Karaté | E3: =IFERROR(INDEX(Clubs!$B$2:$B$20,MATCH(D3,Clubs!$A$2:$A$20,0)),"") -> FAK | F3: H | I3: 66 | K3: Karaté Shidokan | L3: =COUNTIF('Fight card'!$I$6:$I$200,A3)+COUNTIF('Fight card'!$K$6:$K$200,A3) -> 1
A4: =TRIM(B4&" "&C4) -> Keo ZAMBERNARDI | B4: Keo | C4: ZAMBERNARDI | D4: Fighter Academy Karaté | E4: =IFERROR(INDEX(Clubs!$B$2:$B$20,MATCH(D4,Clubs!$A$2:$A$20,0)),"") -> FAK | F4: H | I4: 56 | K4: Shidoboxing | L4: =COUNTIF('Fight card'!$I$6:$I$200,A4)+COUNTIF('Fight card'!$K$6:$K$200,A4) -> 1
A5: =TRIM(B5&" "&C5) -> Lorentz PAYET | B5: Lorentz | C5: PAYET | D5: Fighter Academy Karaté | E5: =IFERROR(INDEX(Clubs!$B$2:$B$20,MATCH(D5,Clubs!$A$2:$A$20,0)),"") -> FAK | F5: H | G5: Benjamins | I5: 35 | K5: Karaté Shidokan | L5: =COUNTIF('Fight card'!$I$6:$I$200,A5)+COUNTIF('Fight card'!$K$6:$K$200,A5) -> 1
A6: =TRIM(B6&" "&C6) -> Melina FOLIO | B6: Melina | C6: FOLIO | D6: Fighter Academy Karaté | E6: =IFERROR(INDEX(Clubs!$B$2:$B$20,MATCH(D6,Clubs!$A$2:$A$20,0)),"") -> FAK | F6: F | G6: Pupilles | I6: 38 | K6: Karaté Shidokan | L6: =COUNTIF('Fight card'!$I$6:$I$200,A6)+COUNTIF('Fight card'!$K$6:$K$200,A6) -> 1 | M6: Exhibition. Catégorie à préciser.
A7: =TRIM(B7&" "&C7) -> Mike MIKE | B7: Mike | C7: MIKE | D7: Fighter Academy Karaté | E7: =IFERROR(INDEX(Clubs!$B$2:$B$20,MATCH(D7,Clubs!$A$2:$A$20,0)),"") -> FAK | F7: H | G7: Seniors | H7: -80 kg | I7: 59 | K7: Shidoboxing | L7: =COUNTIF('Fight card'!$I$6:$I$200,A7)+COUNTIF('Fight card'!$K$6:$K$200,A7) -> 1
A8: =TRIM(B8&" "&C8) -> NOA ZAMBERNARDI | B8: NOA | C8: ZAMBERNARDI | D8: Fighter Academy Karaté | E8: =IFERROR(INDEX(Clubs!$B$2:$B$20,MATCH(D8,Clubs!$A$2:$A$20,0)),"") -> FAK | F8: H | I8: 37 | K8: Shido-MMA | L8: =COUNTIF('Fight card'!$I$6:$I$200,A8)+COUNTIF('Fight card'!$K$6:$K$200,A8) -> 1
A9: =TRIM(B9&" "&C9) -> Raphaël FRAYNAL | B9: Raphaël | C9: FRAYNAL | D9: Fighter Academy Karaté | E9: =IFERROR(INDEX(Clubs!$B$2:$B$20,MATCH(D9,Clubs!$A$2:$A$20,0)),"") -> FAK | F9: H | G9: Benjamins | I9: 24.1 | K9: Karaté Shidokan | L9: =COUNTIF('Fight card'!$I$6:$I$200,A9)+COUNTIF('Fight card'!$K$6:$K$200,A9) -> 1
A10: =TRIM(B10&" "&C10) -> AXEL DUHOU | B10: AXEL | C10: DUHOU | D10: Fukkatsu Kyokushin | E10: =IFERROR(INDEX(Clubs!$B$2:$B$20,MATCH(D10,Clubs!$A$2:$A$20,0)),"") -> FUK | F10: H | I10: 36.5 | K10: Karaté Shidokan | L10: =COUNTIF('Fight card'!$I$6:$I$200,A10)+COUNTIF('Fight card'!$K$6:$K$200,A10) -> 1
A11: =TRIM(B11&" "&C11) -> Basile ABEL | B11: Basile | C11: ABEL | D11: Fukkatsu Kyokushin | E11: =IFERROR(INDEX(Clubs!$B$2:$B$20,MATCH(D11,Clubs!$A$2:$A$20,0)),"") -> FUK | F11: H | G11: Pupilles | I11: 34 | K11: Karaté Shidokan | L11: =COUNTIF('Fight card'!$I$6:$I$200,A11)+COUNTIF('Fight card'!$K$6:$K$200,A11) -> 1
A12: =TRIM(B12&" "&C12) -> Benjamin LEGRAND | B12: Benjamin | C12: LEGRAND | D12: Fukkatsu Kyokushin | E12: =IFERROR(INDEX(Clubs!$B$2:$B$20,MATCH(D12,Clubs!$A$2:$A$20,0)),"") -> FUK | F12: H | G12: Benjamins | I12: 41.5 | K12: Karaté Shidokan | L12: =COUNTIF('Fight card'!$I$6:$I$200,A12)+COUNTIF('Fight card'!$K$6:$K$200,A12) -> 1
A13: =TRIM(B13&" "&C13) -> Bilal SALIMA | B13: Bilal | C13: SALIMA | D13: Fukkatsu Kyokushin | E13: =IFERROR(INDEX(Clubs!$B$2:$B$20,MATCH(D13,Clubs!$A$2:$A$20,0)),"") -> FUK | F13: H | G13: Minimes | I13: 62 | K13: Karaté Shidokan | L13: =COUNTIF('Fight card'!$I$6:$I$200,A13)+COUNTIF('Fight card'!$K$6:$K$200,A13) -> 1
A14: =TRIM(B14&" "&C14) -> Camilya BACAR | B14: Camilya | C14: BACAR | D14: Fukkatsu Kyokushin | E14: =IFERROR(INDEX(Clubs!$B$2:$B$20,MATCH(D14,Clubs!$A$2:$A$20,0)),"") -> FUK | F14: F | G14: Poussins | I14: 24 | K14: Karaté Shidokan | L14: =COUNTIF('Fight card'!$I$6:$I$200,A14)+COUNTIF('Fight card'!$K$6:$K$200,A14) -> 1
A15: =TRIM(B15&" "&C15) -> Clément DELMAS | B15: Clément | C15: DELMAS | D15: Fukkatsu Kyokushin | E15: =IFERROR(INDEX(Clubs!$B$2:$B$20,MATCH(D15,Clubs!$A$2:$A$20,0)),"") -> FUK | F15: H | G15: Seniors | I15: 98 | K15: Karaté Shidokan | L15: =COUNTIF('Fight card'!$I$6:$I$200,A15)+COUNTIF('Fight card'!$K$6:$K$200,A15) -> 1 | M15: Réparti en -80 kg ou +80 kg à la pesée.
A16: =TRIM(B16&" "&C16) -> EDEN BOYER | B16: EDEN | C16: BOYER | D16: Fukkatsu Kyokushin | E16: =IFERROR(INDEX(Clubs!$B$2:$B$20,MATCH(D16,Clubs!$A$2:$A$20,0)),"") -> FUK | F16: H | I16: 34 | K16: Karaté Shidokan | L16: =COUNTIF('Fight card'!$I$6:$I$200,A16)+COUNTIF('Fight card'!$K$6:$K$200,A16) -> 1
A17: =TRIM(B17&" "&C17) -> Elie-Rose THOMAS | B17: Elie-Rose | C17: THOMAS | D17: Fukkatsu Kyokushin | E17: =IFERROR(INDEX(Clubs!$B$2:$B$20,MATCH(D17,Clubs!$A$2:$A$20,0)),"") -> FUK | F17: F | G17: Pupilles | I17: 34 | K17: Karaté Shidokan | L17: =COUNTIF('Fight card'!$I$6:$I$200,A17)+COUNTIF('Fight card'!$K$6:$K$200,A17) -> 1
A18: =TRIM(B18&" "&C18) -> Guillaume PASQUET | B18: Guillaume | C18: PASQUET | D18: Fukkatsu Kyokushin | E18: =IFERROR(INDEX(Clubs!$B$2:$B$20,MATCH(D18,Clubs!$A$2:$A$20,0)),"") -> FUK | F18: H | G18: Seniors | I18: 79 | K18: Karaté Shidokan | L18: =COUNTIF('Fight card'!$I$6:$I$200,A18)+COUNTIF('Fight card'!$K$6:$K$200,A18) -> 1 | M18: Réparti en -80 kg ou +80 kg à la pesée.
A19: =TRIM(B19&" "&C19) -> Inès ICHARD | B19: Inès | C19: ICHARD | D19: Fukkatsu Kyokushin | E19: =IFERROR(INDEX(Clubs!$B$2:$B$20,MATCH(D19,Clubs!$A$2:$A$20,0)),"") -> FUK | F19: F | G19: Pupilles | I19: 27 | K19: Karaté Shidokan | L19: =COUNTIF('Fight card'!$I$6:$I$200,A19)+COUNTIF('Fight card'!$K$6:$K$200,A19) -> 1
A20: =TRIM(B20&" "&C20) -> Kiria BOYER | B20: Kiria | C20: BOYER | D20: Fukkatsu Kyokushin | E20: =IFERROR(INDEX(Clubs!$B$2:$B$20,MATCH(D20,Clubs!$A$2:$A$20,0)),"") -> FUK | F20: F | G20: Pupilles | I20: 23 | K20: Karaté Shidokan | L20: =COUNTIF('Fight card'!$I$6:$I$200,A20)+COUNTIF('Fight card'!$K$6:$K$200,A20) -> 1
A21: =TRIM(B21&" "&C21) -> Liam PROST | B21: Liam | C21: PROST | D21: Fukkatsu Kyokushin | E21: =IFERROR(INDEX(Clubs!$B$2:$B$20,MATCH(D21,Clubs!$A$2:$A$20,0)),"") -> FUK | F21: H | G21: Benjamins | I21: 38 | K21: Karaté Shidokan | L21: =COUNTIF('Fight card'!$I$6:$I$200,A21)+COUNTIF('Fight card'!$K$6:$K$200,A21) -> 1
A22: =TRIM(B22&" "&C22) -> Logan PROST | B22: Logan | C22: PROST | D22: Fukkatsu Kyokushin | E22: =IFERROR(INDEX(Clubs!$B$2:$B$20,MATCH(D22,Clubs!$A$2:$A$20,0)),"") -> FUK | F22: H | G22: Poussins | I22: 23 | K22: Karaté Shidokan | L22: =COUNTIF('Fight card'!$I$6:$I$200,A22)+COUNTIF('Fight card'!$K$6:$K$200,A22) -> 1
A23: =TRIM(B23&" "&C23) -> Mahé PASQUET | B23: Mahé | C23: PASQUET | D23: Fukkatsu Kyokushin | E23: =IFERROR(INDEX(Clubs!$B$2:$B$20,MATCH(D23,Clubs!$A$2:$A$20,0)),"") -> FUK | F23: H | G23: Benjamins | I23: 35 | K23: Karaté Shidokan | L23: =COUNTIF('Fight card'!$I$6:$I$200,A23)+COUNTIF('Fight card'!$K$6:$K$200,A23) -> 1
A24: =TRIM(B24&" "&C24) -> Nathan BABEF | B24: Nathan | C24: BABEF | D24: Fukkatsu Kyokushin | E24: =IFERROR(INDEX(Clubs!$B$2:$B$20,MATCH(D24,Clubs!$A$2:$A$20,0)),"") -> FUK | F24: H | G24: Benjamins | I24: 35 | K24: Karaté Shidokan | L24: =COUNTIF('Fight card'!$I$6:$I$200,A24)+COUNTIF('Fight card'!$K$6:$K$200,A24) -> 1
A25: =TRIM(B25&" "&C25) -> Pierre RODRIGUE | B25: Pierre | C25: RODRIGUE | D25: Fukkatsu Kyokushin | E25: =IFERROR(INDEX(Clubs!$B$2:$B$20,MATCH(D25,Clubs!$A$2:$A$20,0)),"") -> FUK | F25: H | G25: Minimes | I25: 57 | K25: Karaté Shidokan | L25: =COUNTIF('Fight card'!$I$6:$I$200,A25)+COUNTIF('Fight card'!$K$6:$K$200,A25) -> 1
A26: =TRIM(B26&" "&C26) -> Salim YOUSSOUF | B26: Salim | C26: YOUSSOUF | D26: Fukkatsu Kyokushin | E26: =IFERROR(INDEX(Clubs!$B$2:$B$20,MATCH(D26,Clubs!$A$2:$A$20,0)),"") -> FUK | F26: H | G26: Seniors | I26: 106 | K26: Karaté Shidokan | L26: =COUNTIF('Fight card'!$I$6:$I$200,A26)+COUNTIF('Fight card'!$K$6:$K$200,A26) -> 1 | M26: Réparti en -80 kg ou +80 kg à la pesée.
A27: =TRIM(B27&" "&C27) -> Sébastien ELIE | B27: Sébastien | C27: ELIE | D27: Fukkatsu Kyokushin | E27: =IFERROR(INDEX(Clubs!$B$2:$B$20,MATCH(D27,Clubs!$A$2:$A$20,0)),"") -> FUK | F27: H | G27: Seniors | I27: 78 | K27: Karaté Shidokan | L27: =COUNTIF('Fight card'!$I$6:$I$200,A27)+COUNTIF('Fight card'!$K$6:$K$200,A27) -> 1 | M27: Réparti en -80 kg ou +80 kg à la pesée.
A28: =TRIM(B28&" "&C28) -> Antoine RIVIERE | B28: Antoine | C28: RIVIERE | D28: Mandrill Dojo | E28: =IFERROR(INDEX(Clubs!$B$2:$B$20,MATCH(D28,Clubs!$A$2:$A$20,0)),"") -> MAN | F28: H | H28: -35 KG | I28: 35 | K28: Karaté Shidokan | L28: =COUNTIF('Fight card'!$I$6:$I$200,A28)+COUNTIF('Fight card'!$K$6:$K$200,A28) -> 2
A29: =TRIM(B29&" "&C29) -> CEDRIC PAYET | B29: CEDRIC | C29: PAYET | D29: Mandrill Dojo | E29: =IFERROR(INDEX(Clubs!$B$2:$B$20,MATCH(D29,Clubs!$A$2:$A$20,0)),"") -> MAN | F29: H | H29: -100 KG | K29: Karaté Shidokan | L29: =COUNTIF('Fight card'!$I$6:$I$200,A29)+COUNTIF('Fight card'!$K$6:$K$200,A29) -> 2
A30: =TRIM(B30&" "&C30) -> DOMNOE COUILLAUD | B30: DOMNOE | C30: COUILLAUD | D30: Mandrill Dojo | E30: =IFERROR(INDEX(Clubs!$B$2:$B$20,MATCH(D30,Clubs!$A$2:$A$20,0)),"") -> MAN | F30: H | H30: -40 KG | I30: 40 | K30: Karaté Shidokan | L30: =COUNTIF('Fight card'!$I$6:$I$200,A30)+COUNTIF('Fight card'!$K$6:$K$200,A30) -> 1
A31: =TRIM(B31&" "&C31) -> EVE RIVIERE | B31: EVE | C31: RIVIERE | D31: Mandrill Dojo | E31: =IFERROR(INDEX(Clubs!$B$2:$B$20,MATCH(D31,Clubs!$A$2:$A$20,0)),"") -> MAN | F31: F | H31: -55 | I31: 55 | K31: Karaté Shidokan | L31: =COUNTIF('Fight card'!$I$6:$I$200,A31)+COUNTIF('Fight card'!$K$6:$K$200,A31) -> 1
A32: =TRIM(B32&" "&C32) -> GILLES IDMOND | B32: GILLES | C32: IDMOND | D32: Mandrill Dojo | E32: =IFERROR(INDEX(Clubs!$B$2:$B$20,MATCH(D32,Clubs!$A$2:$A$20,0)),"") -> MAN | F32: H | H32: -75 KG | I32: 74.9 | K32: Karaté Shidokan | L32: =COUNTIF('Fight card'!$I$6:$I$200,A32)+COUNTIF('Fight card'!$K$6:$K$200,A32) -> 1
A33: =TRIM(B33&" "&C33) -> HELENA PAYET | B33: HELENA | C33: PAYET | D33: Mandrill Dojo | E33: =IFERROR(INDEX(Clubs!$B$2:$B$20,MATCH(D33,Clubs!$A$2:$A$20,0)),"") -> MAN | F33: F | I33: 55 | K33: Karaté Shidokan | L33: =COUNTIF('Fight card'!$I$6:$I$200,A33)+COUNTIF('Fight card'!$K$6:$K$200,A33) -> 1
A34: =TRIM(B34&" "&C34) -> HUGO GRONDIN | B34: HUGO | C34: GRONDIN | D34: Mandrill Dojo | E34: =IFERROR(INDEX(Clubs!$B$2:$B$20,MATCH(D34,Clubs!$A$2:$A$20,0)),"") -> MAN | F34: H | H34: - 35KG | I34: 35 | K34: Karaté Shidokan | L34: =COUNTIF('Fight card'!$I$6:$I$200,A34)+COUNTIF('Fight card'!$K$6:$K$200,A34) -> 1
A35: =TRIM(B35&" "&C35) -> Lily BEGUE | B35: Lily | C35: BEGUE | D35: Mandrill Dojo | E35: =IFERROR(INDEX(Clubs!$B$2:$B$20,MATCH(D35,Clubs!$A$2:$A$20,0)),"") -> MAN | F35: F | G35: Benjamins | I35: 35 | K35: Karaté Shidokan | L35: =COUNTIF('Fight card'!$I$6:$I$200,A35)+COUNTIF('Fight card'!$K$6:$K$200,A35) -> 2
A36: =TRIM(B36&" "&C36) -> Lucie PAYET | B36: Lucie | C36: PAYET | D36: Mandrill Dojo | E36: =IFERROR(INDEX(Clubs!$B$2:$B$20,MATCH(D36,Clubs!$A$2:$A$20,0)),"") -> MAN | F36: F | G36: Benjamins | I36: 30 | K36: Karaté Shidokan | L36: =COUNTIF('Fight card'!$I$6:$I$200,A36)+COUNTIF('Fight card'!$K$6:$K$200,A36) -> 1
A37: =TRIM(B37&" "&C37) -> MATHIAS DIJOUX | B37: MATHIAS | C37: DIJOUX | D37: Mandrill Dojo | E37: =IFERROR(INDEX(Clubs!$B$2:$B$20,MATCH(D37,Clubs!$A$2:$A$20,0)),"") -> MAN | F37: H | H37: -80 KG | K37: Shido-MMA | L37: =COUNTIF('Fight card'!$I$6:$I$200,A37)+COUNTIF('Fight card'!$K$6:$K$200,A37) -> 1
A38: =TRIM(B38&" "&C38) -> Matys LABRUYERE | B38: Matys | C38: LABRUYERE | D38: Mandrill Dojo | E38: =IFERROR(INDEX(Clubs!$B$2:$B$20,MATCH(D38,Clubs!$A$2:$A$20,0)),"") -> MAN | F38: H | I38: 65 | K38: Karaté Shidokan | L38: =COUNTIF('Fight card'!$I$6:$I$200,A38)+COUNTIF('Fight card'!$K$6:$K$200,A38) -> 1 | M38: full puissance
A39: =TRIM(B39&" "&C39) -> NATHAN RIVIERE | B39: NATHAN | C39: RIVIERE | D39: Mandrill Dojo | E39: =IFERROR(INDEX(Clubs!$B$2:$B$20,MATCH(D39,Clubs!$A$2:$A$20,0)),"") -> MAN | F39: H | H39: -40 | I39: 55 | K39: Karaté Shidokan | L39: =COUNTIF('Fight card'!$I$6:$I$200,A39)+COUNTIF('Fight card'!$K$6:$K$200,A39) -> 1
A40: =TRIM(B40&" "&C40) -> ROBIN TURPIN | B40: ROBIN | C40: TURPIN | D40: Mandrill Dojo | E40: =IFERROR(INDEX(Clubs!$B$2:$B$20,MATCH(D40,Clubs!$A$2:$A$20,0)),"") -> MAN | F40: H | H40: -60 | I40: 60 | K40: Karaté Shidokan | L40: =COUNTIF('Fight card'!$I$6:$I$200,A40)+COUNTIF('Fight card'!$K$6:$K$200,A40) -> 1
...

Sheet Clubs
A1: Club | B1: Code
A2: Fukkatsu Kyokushin | B2: FUK
A3: Mandrill Dojo | B3: MAN
A4: Shogun Kyokushin | B4: SHO
A5: Fighter Academy Karaté | B5: FAK
