Workbook

Sheet Budget prévisionnel
A1: FIGHTER ACADEMY KARATE – SHIDOKAN RÉUNION
A2: Budget prévisionnel – Saison 2026-2027 (format Cerfa n°12156)
A3: Demande de subvention de fonctionnement à la Ville du Tampon
A5: Compte | B5: Libellé | C5: Scénario 5 000 € | D5: Scénario 10 000 €
A6: CHARGES
A7: 60 – Achats
A8: 6064 | B8: Matériel pédagogique et protections de prêt (casques, plastrons, gants, protège-tibias) | C8: 1500 | D8: 2000
A9: 6063 | B9: Tatamis complémentaires (sécurisation des aires de combat) | C9: 1000 | D9: 2500
A10: 6068 | B10: Médailles, diplômes et coupes – Shidokan Challenge 974 | C10: 600 | D10: 1100
A11: 6063 | B11: Matériel section féminine et self-défense | C11: 0 | D11: 1000
A12: 6068 | B12: Matériel courant et pharmacie | C12: =Hypothèses!$B$16 -> 1200 | D12: =Hypothèses!$B$16 -> 1200
A13: 607 | B13: Achats buvette (revendus) | C13: =Hypothèses!$B$21 -> 300 | D13: =Hypothèses!$B$21 -> 300
A14: 61 – Services extérieurs
A15: 616 | B15: Assurance de l'association | C15: =Hypothèses!$B$14 -> 400 | D15: =Hypothèses!$B$14 -> 400
A16: 613 | B16: Location de salle (mise à disposition gratuite par la Ville – valorisée en 86) | C16: 0 | D16: 0
A17: 62 – Autres services extérieurs
A18: 6228 | B18: Formation des encadrants et arbitres (diplômes fédéraux, arbitrage, PSC1) | C18: 1000 | D18: 1500
A19: 623 | B19: Communication, impression, sonorisation – Shidokan Challenge 974 | C19: 400 | D19: 900
A20: 625 | B20: Déplacements en compétition | C20: =Hypothèses!$B$15 -> 0 | D20: =Hypothèses!$B$15 -> 0
A21: 625 | B21: Défraiements des encadrants | C21: =Hypothèses!$B$17 -> 0 | D21: =Hypothèses!$B$17 -> 0
A22: 626 | B22: Frais bancaires, téléphone, site internet | C22: =Hypothèses!$B$18 -> 300 | D22: =Hypothèses!$B$18 -> 300
A23: 65 – Autres charges de gestion courante
A24: 6511 | B24: Licences fédérales | C24: =(Hypothèses!$B$5+Hypothèses!$B$7+Hypothèses!$B$9)*Hypothèses!$B$12 -> 2457 | D24: =(Hypothèses!$B$5+Hypothèses!$B$7+Hypothèses!$B$9)*Hypothèses!$B$12 -> 2457
A25: 6511 | B25: Affiliation Shidokan (par adhérent) | C25: =(Hypothèses!$B$5+Hypothèses!$B$7+Hypothèses!$B$9)*Hypothèses!$B$13 -> 1323 | D25: =(Hypothèses!$B$5+Hypothèses!$B$7+Hypothèses!$B$9)*Hypothèses!$B$13 -> 1323
A26: 6588 | B26: Licences solidaires et stages gratuits pendant les vacances scolaires | C26: 500 | D26: 1000
B27: TOTAL DES CHARGES | C27: =SUM(C7:C26) -> 10980 | D27: =SUM(D7:D26) -> 15980
A29: PRODUITS
A30: 70 – Ventes de produits et prestations
A31: 707 | B31: Recettes buvette (Shidokan Challenge 974) | C31: =Hypothèses!$B$20 -> 900 | D31: =Hypothèses!$B$20 -> 900
A32: 74 – Subventions d'exploitation
A33: 74 | B33: Ville du Tampon (subvention sollicitée) | C33: 5000 | D33: 10000
A34: 74 | B34: Département de La Réunion (à solliciter) | C34: 0 | D34: 0
A35: 74 | B35: Région Réunion (à solliciter) | C35: 0 | D35: 0
A36: 74 | B36: Agence nationale du Sport – PSF via la Ligue (à solliciter) | C36: 0 | D36: 0
A37: 75 – Autres produits de gestion courante
A38: 756 | B38: Cotisations des adhérents (licences incluses) | C38: =Hypothèses!$B$5*Hypothèses!$B$6+Hypothèses!$B$7*Hypothèses!$B$8+Hypothèses!$B$9*Hypothèses!$B$10 -> 17957 | D38: =Hypothèses!$B$5*Hypothèses!$B$6+Hypothèses!$B$7*Hypothèses!$B$8+Hypothèses!$B$9*Hypothèses!$B$10 -> 17957
A39: 7541 | B39: Sponsors et mécénat (L'Assiette Fleurie, DTTP Réunion…) | C39: =Hypothèses!$B$22 -> 500 | D39: =Hypothèses!$B$22 -> 500
B40: Fonds propres mobilisés (+) / excédent prévisionnel (−) – équilibre | C40: =C27-SUM(C30:C39) -> -13377 | D40: =D27-SUM(D30:D39) -> -13377
B41: TOTAL DES PRODUITS | C41: =SUM(C30:C40) -> 10980 | D41: =SUM(D30:D40) -> 15980
A43: CONTRIBUTIONS VOLONTAIRES EN NATURE
...

Sheet Hypothèses
A1: HYPOTHÈSES – à remplacer par les vrais chiffres du club (cellules jaunes)
A2: Les montants ci-dessous sont des EXEMPLES. Modifiez-les : le budget prévisionnel se recalcule automatiquement.
A4: Adhérents
A5: Nombre d'adhérents babies | B5: 10
A6: Cotisation annuelle baby | B6: 239
A7: Nombre d'adhérents enfants | B7: 30
A8: Cotisation annuelle enfant | B8: 259
A9: Nombre d'adhérents ados / adultes / vétérans | B9: 23
A10: Cotisation annuelle ado / adulte | B10: 339
A11: Fonctionnement courant
A12: Prix de la licence fédérale par adhérent | B12: 39
A13: Affiliation Shidokan par adhérent | B13: 21
A14: Assurance de l'association | B14: 400
A15: Déplacements en compétition (transport, engagements) | B15: 0
A16: Matériel courant et pharmacie | B16: 1200
A17: Défraiements des encadrants (kilomètres, frais) | B17: 0
A18: Frais bancaires, téléphone, site internet | B18: 300
A19: Événement et partenaires
A20: Recettes buvette (Shidokan Challenge) | B20: 900
A21: Achats buvette | B21: 300
A22: Sponsors / mécénat (L'Assiette Fleurie, DTTP Réunion…) | B22: 500
A23: Contributions en nature (valorisation)
A24: Heures d'utilisation de la salle municipale par an | B24: 216
A25: Valeur horaire de la mise à disposition de la salle | B25: 20
A26: Heures de bénévolat par an (encadrement + événements) | B26: 650
A27: Valeur horaire du bénévolat (base SMIC – à vérifier) | B27: 12
